Workbook

Sheet Instructions
B2: Indian Aquaculture GHG & Carbon Reduction Assessment Tool
B3: Version 3.3 (Excel) — IMC | Pangasius | Red Pacu | P. vannamei | P. monodon
B5: How this workbook works
B6: This is a linked calculation engine, not a static sheet. Select a Culture Type on the Dashboard and every downstream module — growth, feed, pond emissions, energy, carbon accounting — recalculates automatically from the Species Database and Feed Database.
B8: Sheet order & purpose
B9: 1. Dashboard — select culture type, enter farm details, view all headline results (production, GHG and cost/profit) in one place.
B10: 2. Species Database — stocking, growth, harvest-stage, survival, aeration and FCR (average + improved target) parameters for all 5 culture types.
B11: 3. Feed Database — ingredient/stage-level nutrient composition, emission factors and sourcing notes; blends into the feed profile used by each species.
B12: 4. Growth & Feed Model — period-by-period biomass growth (specific growth rate model) and cumulative feed requirement.
B13: 5. Harvest Schedule — cascading partial/final (or count-stage) harvest events; population and biomass recalculate automatically after each event; determines actual Total Production.
B14: 6. Feed Emission Model — feed manufacturing CO2e, and the feed carbon/nitrogen mass balance (retained vs. lost).
B15: 7. Pond Emission Model — converts carbon/nitrogen lost to the pond into CH4 (with an oxidation correction) and N2O.
... B45: See the new Change Log sheet for the full, version-by-version list of what changed and what remains deferred.

Sheet Change Log
A1: Change Log
A3: Version | B3: Change | C3: Sheet(s) Affected
A4: v2.1 | B4: IMC Species Database updated to reported farm practice (6,250/ha; 150g stocking; 1/1.5kg partial/final harvest; FCR 3.0/2.5). | C4: Species Database
A5: v2.1 | B5: Harvest Schedule rebuilt as a cascading population model — event weights pulled from the growth curve; population/biomass carry forward after each event. | C5: Harvest Schedule
A6: v2.1 | B6: New Economics Module: feed/electricity/diesel/labour/seed/probiotics cost, gross income, net profit, cost/profit per kg. | C6: Economics Module
A7: v2.1 | B7: Dashboard expanded with cost and carbon-fate outputs; Scientific References rebuilt with a dedicated Citation column. | C7: Dashboard, Scientific References
A8: v2.2 | B8: Added Lime & Fertilizer Emissions (IPCC Tier 1 defaults), folded into Gross Emission. | C8: Pond Emission Model, Carbon Accounting
A9: v2.2 | B9: Added Annual Rollup (Multi-Crop) to Economics Module. | C9: Economics Module
A10: v2.2 | B10: New Sensitivity Analysis sheet: FCR, Survival and Energy-use scenarios vs. Net Emission, Emission Intensity, Net Profit. | C10: Sensitivity Analysis
A11: v2.3 | B11: Added GWP AR5/AR6 toggle (later moved to Dashboard in v3.0), N2O-N EF presets (0.71%/1.8%/Custom), and an Anaerobic Fraction Adjustment Factor (0.8-1.5). | C11: Pond Emission Model
A12: v2.3 | B12: Added a Stage FCR Multiplier column to the Growth Model's period table (default 1.00, editable per period). | C12: Growth & Feed Model
A13: v2.3 | B13: Added Generator Efficiency (informational) and solar-sizing guidance. | C13: Energy Module
A14: v2.3 | B14: Added an optional, strongly-caveated Sediment Organic Carbon Sequestration estimate (informational only, NOT counted in Net Emission) and an Edible-Yield Emission Intensity metric. | C14: Carbon Accounting
... A25: v3.1 | B25: Replaced the redox-potential (Eh) calibration guidance for Anaerobic Fraction with a Dissolved Oxygen + Hydrogen Sulphate (H2S) rule, grounded in an actual regional aqua lab water report — redox probes are not realistically available on-farm, but DO and H2S are standard fields on every lab report farmers already receive. | C25: Pond Emission Model
A26: v3.1
A27: v3.2
A28: v3.2
A29: v3.2
A30: v3.2
A31: v3.3
A32: Not yet implemented (deferred)
A33: • Charts (emissions breakdown pie, baseline vs. improved bars, sensitivity tornado) — candidate for next revision.
A34: • Cell/sheet protection (locking formulas while keeping inputs editable) — candidate for next revision.
A35: • Dashboard traffic-light Validation Score and prominent Harvest-vs-Growth variance flag — the variance figure exists on Harvest Schedule today but is not yet mirrored to the Dashboard with conditional formatting.
A36: • True multi-pond/multi-farm support (independent species/size per pond) — only single-pond-scaled-by-crops-per-year exists today.
A37: • One-click automated PDF export — manual Print/Export to PDF on the Report sheet works today.
... A39: • Pangasius, Red Pacu, P. vannamei and P. monodon species/growth parameters remain illustrative, not farm-validated.
A41: v3.4 | B41: 2026-08-18 | C41: Dynamic field-data MRV engine for IMC: geospatial SPF, actual feed mix, WQ/plankton log, PQI/natural-feed offset, dynamic anaerobic fraction, cyanobacteria N2O adjustment, DO stress, Punch Bag, measured SOC, C:N risk, IMC aeration lock, CEA EF version control, MRV integrity checks.

Sheet Dashboard
A1: Indian Aquaculture GHG & Carbon Reduction Dashboard
A2: Select culture type and enter farm details. All results below update automatically.
A3: After changing Culture Type: update quantities on Harvest Schedule and farm-record inputs. For IMC, aeration is hard-locked to zero. Use the new field-data blocks for MRV.
A4: A. Farm & Crop Details
A5: Culture Type | B5: IMC | C5: select | D5: Choose from the 5 supported culture types
A6: Farm Name | B6: Sample Farm | C6: text
A7: Farmer Name | B7: Farmer Name | C7: text
A8: State | B8: Andhra Pradesh | C8: text
A9: District | B9: District Name | C9: text
A10: Pond Area | B10: 1 | C10: ha | D10: Total water spread area
A11: Average Water Depth | B11: 1.5 | C11: m | D11: For reference / MRV context
A12: Number of Crops per Year | B12: 1 | C12: crops/yr | D12: 1 for carp/pangasius; 2 for many shrimp systems
A13: Farm-Reported FCR (optional override) | C13: ratio | D13: Leave blank to use the species default FCR
A14: GWP Framework Version | B14: AR5 | C14: AR5 / AR6 | D14: AR5 = IPCC 2013 (CH4 GWP=28, N2O GWP=265); AR6 = IPCC 2021 (CH4 GWP=27 biogenic, N2O GWP=273). Drives GWP values used in the Pond Emission Model and all downstream sheets.
A15: B. Selected Species Parameters (auto-filled from Species Database)
A16: Category | B16: =INDEX('Species Database'!$B$5:$B$9,MATCH($B$5,'Species Database'!$A$5:$A$9,0)) -> Freshwater Fish (polyculture)
A17: Stocking Density | B17: =INDEX('Species Database'!$C$5:$C$9,MATCH($B$5,'Species Database'!$A$5:$A$9,0)) -> 6250
A18: Stocking Weight | B18: =INDEX('Species Database'!$D$5:$D$9,MATCH($B$5,'Species Database'!$A$5:$A$9,0)) -> 150
A19: Partial Harvest Weight | B19: =INDEX('Species Database'!$E$5:$E$9,MATCH($B$5,'Species Database'!$A$5:$A$9,0)) -> 1000
A20: Final Harvest Weight | B20: =INDEX('Species Database'!$F$5:$F$9,MATCH($B$5,'Species Database'!$A$5:$A$9,0)) -> 1500
A21: Culture Duration | B21: =INDEX('Species Database'!$G$5:$G$9,MATCH($B$5,'Species Database'!$A$5:$A$9,0)) -> 240
A22: Survival | B22: =INDEX('Species Database'!$H$5:$H$9,MATCH($B$5,'Species Database'!$A$5:$A$9,0)) -> 0.8
A23: Aeration Required | B23: =INDEX('Species Database'!$I$5:$I$9,MATCH($B$5,'Species Database'!$A$5:$A$9,0)) -> FALSE
A24: Average FCR | B24: =INDEX('Species Database'!$J$5:$J$9,MATCH($B$5,'Species Database'!$A$5:$A$9,0)) -> 3
A25: Improved FCR Target | B25: =INDEX('Species Database'!$K$5:$K$9,MATCH($B$5,'Species Database'!$A$5:$A$9,0)) -> 2.5
A26: Feed Manufacturing EF | B26: =INDEX('Species Database'!$L$5:$L$9,MATCH($B$5,'Species Database'!$A$5:$A$9,0)) -> 0.615
A27: Feed Carbon Content | B27: =INDEX('Species Database'!$M$5:$M$9,MATCH($B$5,'Species Database'!$A$5:$A$9,0)) -> 0.3925
A28: Feed Nitrogen Content | B28: =INDEX('Species Database'!$N$5:$N$9,MATCH($B$5,'Species Database'!$A$5:$A$9,0)) -> 0.038928
A29: Actual Feed Used in Crop (MRV override) | C29: kg | D29: Enter verified feed actually consumed during this crop; leave blank to use modeled feed requirement.
A30: Actual FCR Used in Model | B30: =IF($B$13="",B24,$B$13) -> 3
A31: Improved FCR Target (species reference) | B31: =B25 -> 2.5 | C31: Compare against Improved Farming Scenario's modelled result
A32: Punch Bag Feeding System | B32: No | C32: Yes/No | D32: IMC management input. If Yes, Growth Model applies the configured FCR improvement once; do not double-count in Improved Scenario.
A33: C. Key Outputs — Baseline Crop Summary
A34: Total Production | B34: ='Harvest Schedule'!B15 -> 8777.4226 | C34: kg
A35: Total Feed Required | B35: ='Growth & Feed Model'!B25 -> 20800.267 | C35: kg
A36: Feed Cost | B36: ='Economics Module'!B22 -> 936012 | C36: Rs
A37: Feed Carbon | B37: ='Feed Emission Model'!B16 -> 8164.1046 | C37: kg C
A38: Carbon Retained in Biomass | B38: ='Feed Emission Model'!B17 -> 1796.103 | C38: kg C
A39: Carbon Lost to Pond | B39: ='Feed Emission Model'!B18 -> 6368.0016 | C39: kg C
A40: CH4 Emission (CO2e) | B40: ='Pond Emission Model'!B24 -> 35.660809 | C40: tCO2e
...

Sheet Species Database
A1: Species Database
A2: Editable defaults (yellow). Feed Carbon/Nitrogen/EF columns are linked formulas pulling the blended profile from the Feed Database sheet. IMC values reflect reported farm practice (v2.1); other species remain illustrative pending validation.
A4: Culture Type | B4: Category | C4: Stocking Density (no./ha) | D4: Stocking Weight (g) | E4: Partial Harvest Weight (g) | F4: Final Harvest Weight (g) | G4: Culture Duration (days) | H4: Survival (%) | I4: Aeration Required | J4: Average FCR (Baseline) | K4: Improved FCR (Target) | L4: Feed Mfg. EF (kgCO2e/kg) | M4: Feed Carbon Content (%) | N4: Feed Nitrogen Content (%) | O4: Notes / Source | P4: Aeration Lock | Q4: Paddlewheel Hours | R4: Blower Hours
A5: IMC | B5: Freshwater Fish (polyculture) | C5: 6250 | D5: 150 | E5: 1000 | F5: 1500 | G5: 240 | H5: 0.8 | I5: =FALSE() -> FALSE | J5: 3 | K5: 2.5 | L5: ='Feed Database'!E47 -> 0.615 | M5: ='Feed Database'!C47 -> 0.3925 | N5: ='Feed Database'!D47 -> 0.038928 | O5: IMC hard constraint: no mechanical aeration; Paddlewheel/Blower hours must remain zero. Parameters otherwise reflect reported AP farm practice. | P5: LOCKED | Q5: 0 | R5: 0
A6: Pangasius | B6: Freshwater Fish (monoculture) | C6: 25000 | D6: 5 | F6: 1000 | G6: 240 | H6: 0.85 | I6: No | J6: 1.6 | K6: 1.4 | L6: ='Feed Database'!E48 -> 1.81 | M6: ='Feed Database'!C48 -> 0.395 | N6: ='Feed Database'!D48 -> 0.04416 | O6: Illustrative intensive pond defaults — not yet validated against farm records. Single (final) harvest assumed — set Partial Harvest Weight if the farm thins the pond. | P6: OPEN | Q6: 0 | R6: 0
A7: Red Pacu | B7: Freshwater Fish (monoculture) | C7: 8000 | D7: 10 | F7: 800 | G7: 240 | H7: 0.85 | I7: Yes | J7: 1.8 | K7: 1.55 | L7: ='Feed Database'!E49 -> 1.81 | M7: ='Feed Database'!C49 -> 0.395 | N7: ='Feed Database'!D49 -> 0.04512 | O7: Illustrative defaults — not yet validated against farm records. | P7: OPEN | Q7: 0 | R7: 0
A8: P. vannamei | B8: Shrimp | C8: 400000 | D8: 0.005 | E8: 16.7 | F8: 33.3 | G8: 120 | H8: 0.75 | I8: Yes | J8: 1.5 | K8: 1.35 | L8: ='Feed Database'!E50 -> 2.46 | M8: ='Feed Database'!C50 -> 0.391 | N8: ='Feed Database'!D50 -> 0.05536 | O8: Illustrative defaults — not yet validated. Count-stage harvests (80/60/40/30 count) are modelled event-by-event on the Harvest Schedule sheet; Partial/Final Harvest Weight here are reference points only (60 count / 30 count). | P8: OPEN | Q8: 0 | R8: 0
A9: P. monodon | B9: Shrimp | C9: 150000 | D9: 0.01 | E9: 33.3 | F9: 66.7 | G9: 150 | H9: 0.7 | I9: Yes | J9: 1.7 | K9: 1.5 | L9: ='Feed Database'!E51 -> 2.43 | M9: ='Feed Database'!C51 -> 0.3915 | N9: ='Feed Database'!D51 -> 0.05488 | O9: Illustrative defaults — not yet validated. First thinning at 30 count, final harvest averaged at 10-20 count (66.7 g) — modelled on the Harvest Schedule sheet. | P9: OPEN | Q9: 0 | R9: 0

Sheet Feed Database
A1: Feed Database
A2: Enter feed mix % by ingredient/stage (each block must sum to 100%). Blended rows compute the weighted-average nutrient and emission profile used by Species Database.
A4: A. IMC — Ingredient Mix
A5: Ingredient | B5: Protein % | C5: Fat % | D5: Fibre % | E5: Carbon % | F5: Nitrogen % (=Protein/6.25) | G5: Emission Factor (kgCO2e/kg) | H5: % of IMC Feed Mix | I5: Actual Purchased kg | J5: Actual Mix %
A6: De-oiled Bran (DOB) | B6: 0.169 | C6: 0.015 | D6: 0.096 | E6: 0.38 | F6: =B6/6.25 -> 0.02704 | G6: 0.4 | H6: 0.7 | J6: =IF(SUM($I$6:$I$9)=0,H6,I6/SUM($I$6:$I$9)) -> 0.7
A7: Groundnut Cake (GNC) | B7: 0.45 | C7: 0.07 | D7: 0.06 | E7: 0.42 | F7: =B7/6.25 -> 0.072 | G7: 1.2 | H7: 0.15 | J7: =IF(SUM($I$6:$I$9)=0,H7,I7/SUM($I$6:$I$9)) -> 0.15
A8: Soybean Meal (SBM) | B8: 0.44 | C8: 0.015 | D8: 0.07 | E8: 0.41 | F8: =B8/6.25 -> 0.0704 | G8: 1.1 | H8: 0.1 | J8: =IF(SUM($I$6:$I$9)=0,H8,I8/SUM($I$6:$I$9)) -> 0.1
A9: DDGS | B9: 0.27 | C9: 0.1 | D9: 0.08 | E9: 0.45 | F9: =B9/6.25 -> 0.0432 | G9: 0.9 | H9: 0.05 | J9: =IF(SUM($I$6:$I$9)=0,H9,I9/SUM($I$6:$I$9)) -> 0.05
A10: Mix % check (must = 100%) | H10: =SUM(H6:H9) -> 1 | J10: =SUM(J6:J9) -> 1
A11: IMC Blended Feed Profile | B11: =IFERROR(SUMPRODUCT($J$6:$J$9,$B$6:$B$9)/SUM($J$6:$J$9),"") -> 0.2433 | E11: =IFERROR(SUMPRODUCT($J$6:$J$9,$E$6:$E$9)/SUM($J$6:$J$9),"") -> 0.3925 | F11: =IFERROR(SUMPRODUCT($J$6:$J$9,$F$6:$F$9)/SUM($J$6:$J$9),"") -> 0.038928 | G11: =IFERROR(SUMPRODUCT($J$6:$J$9,$G$6:$G$9)/SUM($J$6:$J$9),"") -> 0.615 | I11: Actual kg if entered; reference mix otherwise | J11: =IF(SUM($I$6:$I$9)=0,"REFERENCE MIX","INVOICE-DERIVED") -> REFERENCE MIX
A12: MRV note: Actual Purchased kg drives the blended feed profile when entered. Keep invoices/batch references in the adjacent Notes/Source field or farm records.
A14: B. Pangasius — Feed Stages
A15: Feed Stage | B15: Protein % | C15: Carbon % | D15: Nitrogen % (=Protein/6.25) | E15: Emission Factor (kgCO2e/kg) | F15: % of Total Feed
A16: Starter | B16: 0.3 | C16: 0.4 | D16: =B16/6.25 -> 0.048 | E16: 2 | F16: 0.3
A17: Grower | B17: 0.28 | C17: 0.4 | D17: =B17/6.25 -> 0.0448 | E17: 1.8 | F17: 0.45
A18: Finisher | B18: 0.24 | C18: 0.38 | D18: =B18/6.25 -> 0.0384 | E18: 1.6 | F18: 0.25
A19: Mix % check (must = 100%) | F19: =SUM(F16:F18) -> 1
A20: Blended Feed Profile | B20: =SUMPRODUCT(F16:F18,B16:B18)/SUM(F16:F18) -> 0.276 | C20: =SUMPRODUCT(F16:F18,C16:C18)/SUM(F16:F18) -> 0.395 | D20: =SUMPRODUCT(F16:F18,D16:D18)/SUM(F16:F18) -> 0.04416 | E20: =SUMPRODUCT(F16:F18,E16:E18)/SUM(F16:F18) -> 1.81
A21: Source: Indicative commercial pangasius feed protein/carbon values — cross-check against feed mill spec sheets (e.g., CIFA/ICAR pangasius nutrition literature).
A23: C. Red Pacu — Feed Stages
A24: Feed Stage | B24: Protein % | C24: Carbon % | D24: Nitrogen % (=Protein/6.25) | E24: Emission Factor (kgCO2e/kg) | F24: % of Total Feed
A25: Starter | B25: 0.32 | C25: 0.4 | D25: =B25/6.25 -> 0.0512 | E25: 2 | F25: 0.3
A26: Grower | B26: 0.28 | C26: 0.4 | D26: =B26/6.25 -> 0.0448 | E26: 1.8 | F26: 0.45
A27: Finisher | B27: 0.24 | C27: 0.38 | D27: =B27/6.25 -> 0.0384 | E27: 1.6 | F27: 0.25
A28: Mix % check (must = 100%) | F28: =SUM(F25:F27) -> 1
A29: Blended Feed Profile | B29: =SUMPRODUCT(F25:F27,B25:B27)/SUM(F25:F27) -> 0.282 | C29: =SUMPRODUCT(F25:F27,C25:C27)/SUM(F25:F27) -> 0.395 | D29: =SUMPRODUCT(F25:F27,D25:D27)/SUM(F25:F27) -> 0.04512 | E29: =SUMPRODUCT(F25:F27,E25:E27)/SUM(F25:F27) -> 1.81
A30: Source: Indicative commercial feed protein/carbon values, aligned to pangasius-equivalent stages pending Red Pacu-specific data — cross-check against feed mill spec sheets.
A32: D. Shrimp — Feed Stages (Species A = P. vannamei, Species B = P. monodon)
A33: Feed Stage | B33: Protein % | C33: Carbon % | D33: Nitrogen % (=Protein/6.25) | E33: Emission Factor (kgCO2e/kg) | F33: % Total Feed (Species A) | G33: % Total Feed (Species B)
A34: Pre-Starter | B34: 0.4 | C34: 0.38 | D34: =B34/6.25 -> 0.064 | E34: 3 | F34: 0.05 | G34: 0.05
A35: Starter | B35: 0.38 | C35: 0.38 | D35: =B35/6.25 -> 0.0608 | E35: 2.8 | F35: 0.15 | G35: 0.15
A36: Grower I | B36: 0.36 | C36: 0.39 | D36: =B36/6.25 -> 0.0576 | E36: 2.6 | F36: 0.25 | G36: 0.2
A37: Grower II | B37: 0.34 | C37: 0.39 | D37: =B37/6.25 -> 0.0544 | E37: 2.4 | F37: 0.25 | G37: 0.25
A38: Grower III | B38: 0.32 | C38: 0.4 | D38: =B38/6.25 -> 0.0512 | E38: 2.2 | F38: 0.2 | G38: 0.2
A39: Finisher | B39: 0.3 | C39: 0.4 | D39: =B39/6.25 -> 0.048 | E39: 2 | F39: 0.1 | G39: 0.15
A40: Mix % check (must = 100%) | F40: =SUM(F34:F39) -> 1 | G40: =SUM(G34:G39) -> 1
A41: Blended Feed Profile (Species A) | B41: =SUMPRODUCT(F34:F39,B34:B39)/SUM(F34:F39) -> 0.346 | C41: =SUMPRODUCT(F34:F39,C34:C39)/SUM(F34:F39) -> 0.391 | D41: =SUMPRODUCT(F34:F39,D34:D39)/SUM(F34:F39) -> 0.05536 | E41: =SUMPRODUCT(F34:F39,E34:E39)/SUM(F34:F39) -> 2.46
A42: Blended Feed Profile (Species B) | B42: =SUMPRODUCT(G34:G39,B34:B39)/SUM(G34:G39) -> 0.343 | C42: =SUMPRODUCT(G34:G39,C34:C39)/SUM(G34:G39) -> 0.3915 | D42: =SUMPRODUCT(G34:G39,D34:D39)/SUM(G34:G39) -> 0.05488 | E42: =SUMPRODUCT(G34:G39,E34:E39)/SUM(G34:G39) -> 2.43
A43: Source: Indicative commercial shrimp feed protein/carbon values by stage — cross-check against CIBA (ICAR-Central Institute of Brackishwater Aquaculture) shrimp feed literature and feed mill spec sheets.
A45: E. Blended Feed Profile Summary (used by Species Database)
...

Sheet Growth & Feed Model
A1: Growth & Feed Model
A2: Specific Growth Rate (SGR) model from Dashboard/Species Database inputs. Do not edit — pulls automatically.
A4: Reference Inputs (from Dashboard) | J4: Dynamic Ecological Adjustment Engine
A5: Stocking Density | B5: =Dashboard!$B$17 -> 6250 | C5: no./ha | J5: Seasonal Photosynthesis Factor | K5: =Dashboard!$B$56 -> 1 | L5: 0–1 | M5: Derived from latitude and crop dates
A6: Pond Area | B6: =Dashboard!$B$10 -> 1 | C6: ha | J6: Average PQI | K6: =IF(COUNT('Water Quality & Plankton Log'!$A$6:$A$65)=0,0,MAX(0,MIN(1,0.6*MIN(1,(AVERAGE('Water Quality & Plankton Log'!$G$6:$G$65)+AVERAGE('Water Quality & Plankton Log'!$H$6:$H$65))/0.6)+0.4*MIN(1,AVERAGE('Water Quality & Plankton Log'!$J$6:$J$65)/3)))) -> 0 | L6: 0–1 | M6: Diatoms + green algae + zooplankton
A7: Total Stocked Number | B7: =B5*B6 -> 6250 | C7: nos. | D7: Formula: Stocking density x Pond area | J7: WQ Data Completeness | K7: ='Pond Emission Model'!$G$46 -> 0 | L7: fraction | M7: Weekly data completeness
A8: Initial Weight | B8: =Dashboard!$B$18 -> 150 | C8: g | J8: Average Cyanobacteria % | K8: ='Pond Emission Model'!$G$45 | L8: fraction | M8: Field log average
A9: Harvest Weight | B9: =Dashboard!$B$20 -> 1500 | C9: g | J9: Natural Feed Offset | K9: =IF($K$7<0.75,0,IF(AND(ISNUMBER($K$8),$K$8>0.5),MIN(0.05,0.2*$K$6*$K$5),MIN(0.2,0.2*$K$6*$K$5))) -> 0 | L9: fraction | M9: Bounded natural-food credit; disabled when WQ data <75%
A10: Culture Duration | B10: =Dashboard!$B$21 -> 240 | C10: days | J10: Punch Bag Feeding | K10: =Dashboard!$B$32 -> No | L10: Yes/No | M10: Management input
A11: Survival | B11: =Dashboard!$B$22 -> 0.8 | C11: % | J11: Punch Bag FCR Improvement | K11: =IF($K$10="Yes",12.5%,0) -> 0 | L11: fraction | M11: Single applied FCR improvement; 10% wastage reduction retained as a KPI, not double-counted
A12: FCR Used | B12: =Dashboard!$B$30 -> 3 | C12: ratio | J12: Pre-Dawn DO Stress Factor | K12: =IF($K$7<0.75,1,IFERROR(IF(AVERAGE('Water Quality & Plankton Log'!$C$6:$C$65)<3,1.1,1),1)) -> 1 | L12: multiplier | M12: 10% FCR penalty when predawn DO <3 mg/L and adequate WQ records exist
A13: Specific Growth Rate constant (k) | B13: =LN(B9/B8)/B10 -> 0.0095941046 | C13: per day | D13: Formula: LN(Harvest wt / Initial wt) / Duration | J13: Effective FCR | K13: =Dashboard!$B$30*(1-$K$11)*$K$12 -> 3 | L13: ratio | M13: Feeds the period-by-period feed equations
J14: Punch Bag Wastage KPI | K14: =IF($K$10="Yes",10%,0) -> 0 | L14: fraction | M14: Informational; do not multiply again into FCR
A15: Period-by-Period Growth & Feed Table (6 equal periods) | J15: Data Quality Grade | K15: =IF($K$7>=0.9,"A",IF($K$7>=0.75,"B",IF($K$7>0,"C","D"))) -> D | L15: grade | M15: A≥90%, B≥75%, C<75%, D=no field data
A16: Period | B16: Day | C16: Individual Weight (g) | D16: Surviving Population | E16: Standing Biomass (kg) | F16: Period Feed Required (kg) | G16: Cumulative Feed (kg) | H16: Stage FCR Multiplier
A17: 1 | B17: =$B$10/6*1 -> 40 | C17: =IF($B$29="Logistic (Sigmoidal)",$B$30/(1+(($B$30-$B$8)/$B$8)*EXP(-$B$31*B17)),$B$8*EXP($B$13*B17)) -> 220.16989 | D17: =$B$7*(1-(1-$B$11)*(B17/$B$10)) -> 6041.6667 | E17: =C17*D17/1000 -> 1330.1931 | F17: =(MAX(0,E17-($B$8*$B$7/1000))+$B$32*(($B$7-D17)*(($B$8+C17)/2)/1000))*$K$13*(1-$K$9)*H17 -> 1235.9183 | G17: =F17 -> 1235.9183 | H17: 1
A18: 2 | B18: =$B$10/6*2 -> 80 | C18: =IF($B$29="Logistic (Sigmoidal)",$B$30/(1+(($B$30-$B$8)/$B$8)*EXP(-$B$31*B18)),$B$8*EXP($B$13*B18)) -> 323.1652 | D18: =$B$7*(1-(1-$B$11)*(B18/$B$10)) -> 5833.3333 | E18: =C18*D18/1000 -> 1885.1304 | F18: =(MAX(0,E18-E17)+$B$32*((D17-D18)*((C17+C18)/2)/1000))*$K$13*(1-$K$9)*H18 -> 1749.7079 | G18: =G17+F18 -> 2985.6262 | H18: 1
A19: 3 | B19: =$B$10/6*3 -> 120 | C19: =IF($B$29="Logistic (Sigmoidal)",$B$30/(1+(($B$30-$B$8)/$B$8)*EXP(-$B$31*B19)),$B$8*EXP($B$13*B19)) -> 474.34165 | D19: =$B$7*(1-(1-$B$11)*(B19/$B$10)) -> 5625 | E19: =C19*D19/1000 -> 2668.1718 | F19: =(MAX(0,E19-E18)+$B$32*((D18-D19)*((C18+C19)/2)/1000))*$K$13*(1-$K$9)*H19 -> 2473.7347 | G19: =G18+F19 -> 5459.3609 | H19: 1
A20: 4 | B20: =$B$10/6*4 -> 160 | C20: =IF($B$29="Logistic (Sigmoidal)",$B$30/(1+(($B$30-$B$8)/$B$8)*EXP(-$B$31*B20)),$B$8*EXP($B$13*B20)) -> 696.23833 | D20: =$B$7*(1-(1-$B$11)*(B20/$B$10)) -> 5416.6667 | E20: =C20*D20/1000 -> 3771.2909 | F20: =(MAX(0,E20-E19)+$B$32*((D19-D20)*((C19+C20)/2)/1000))*$K$13*(1-$K$9)*H20 -> 3492.2606 | G20: =G19+F20 -> 8951.6215 | H20: 1
A21: 5 | B21: =$B$10/6*5 -> 200 | C21: =IF($B$29="Logistic (Sigmoidal)",$B$30/(1+(($B$30-$B$8)/$B$8)*EXP(-$B$31*B21)),$B$8*EXP($B$13*B21)) -> 1021.9381 | D21: =$B$7*(1-(1-$B$11)*(B21/$B$10)) -> 5208.3333 | E21: =C21*D21/1000 -> 5322.5943 | F21: =(MAX(0,E21-E20)+$B$32*((D20-D21)*((C20+C21)/2)/1000))*$K$13*(1-$K$9)*H21 -> 4922.3752 | G21: =G20+F21 -> 13873.997 | H21: 1
A22: 6 | B22: =$B$10/6*6 -> 240 | C22: =IF($B$29="Logistic (Sigmoidal)",$B$30/(1+(($B$30-$B$8)/$B$8)*EXP(-$B$31*B22)),$B$8*EXP($B$13*B22)) -> 1500 | D22: =$B$7*(1-(1-$B$11)*(B22/$B$10)) -> 5000 | E22: =C22*D22/1000 -> 7500 | F22: =(MAX(0,E22-E21)+$B$32*((D21-D22)*((C21+C22)/2)/1000))*$K$13*(1-$K$9)*H22 -> 6926.27 | G22: =G21+F22 -> 20800.267 | H22: 1
A23: Dynamic field-data adjustments (v3.4): effective FCR includes Punch Bag and DO stress; natural-feed offset is bounded by SPF/PQI and disabled below 75% WQ completeness. Population/harvest cascade remains unchanged.
A24: Growth Model Outputs
A25: Total Feed Required (Growth Model estimate) | B25: =G22 -> 20800.267 | C25: kg | D25: Formula: Cumulative feed at final period
A26: Estimated Standing Biomass at Culture End | B26: =E22 -> 7500 | C26: kg | D26: Reference figure for Harvest Schedule cross-check
A28: Advanced Growth Options (v3.0)
A29: Growth Curve Type | B29: Exponential (SGR) | C29: Exponential / Logistic | D29: Exponential (SGR) overestimates late-stage biomass for some systems; Logistic (Sigmoidal) tapers growth as the stock approaches harvest weight and is often more realistic, especially for shrimp
A30: Logistic Asymptotic Weight (Wmax) | B30: =B9/0.98 -> 1530.6122 | C30: g | D30: Formula: Harvest weight / 0.98 — sets the curve's ceiling just above the target harvest weight
A31: Logistic Growth Rate (r) | B31: =-LN((B30/B9-1)*B8/(B30-B8))/B10 -> 0.025464447 | C31: per day | D31: Solved so the logistic curve passes through the harvest weight at the culture duration
A32: Mortality Feed Consumption Factor | B32: 0.5 | C32: fraction | D32: Fraction of a full ration consumed by stock that die during the period, before death — 0 ignores mortality feed entirely, 1 assumes dying stock ate a full ration throughout the period. Applied to the Period Feed Required formula below.
A34: Empirical IMC Feeding Rate Reference (v3.2, informational — not wired into the calculation)
A35: A published field survey (2010) of IMC feeding rates by body weight, using %body-weight/day feeding rates for two regimes: sinking pellet (20% protein) + de-oiled rice bran, versus floating feed alone (22% protein). Shown here as a cross-check on the Average FCR entered in the Species Database, not as a replacement for farm-reported data — real farm FCR reflects feed wastage and water-quality losses that an idealized feeding-rate table does not capture.
A36: Initial Weight (kg) | B36: Monthly Growth (kg/month) | C36: Sinking Feed Rate (%BW/day, 20% pr.) | D36: DOB Feed Rate (%BW/day) | E36: Total (Sinking+DOB) Rate (%BW/day) | F36: Floating Feed Rate (%BW/day, 22% pr.) | G36: Implied Monthly FCR (Sinking+DOB / Floating)
A37: 0.1 | B37: 0.1 | C37: 2.64 | D37: 4 | E37: 6.64 | F37: 3.3 | G37: =CONCATENATE(ROUND(((A37+B37/2)*(E37/100)*30)/B37,2)," / ",ROUND(((A37+B37/2)*(F37/100)*30)/B37,2)) -> 2.99 / 1.49
A38: 0.2 | B38: 0.12 | C38: 1.6 | D38: 2.4 | E38: 4 | F38: 2 | G38: =CONCATENATE(ROUND(((A38+B38/2)*(E38/100)*30)/B38,2)," / ",ROUND(((A38+B38/2)*(F38/100)*30)/B38,2)) -> 2.6 / 1.3
A39: 0.32 | B39: 0.12 | C39: 1 | D39: 1.5 | E39: 2.5 | F39: 1.4 | G39: =CONCATENATE(ROUND(((A39+B39/2)*(E39/100)*30)/B39,2)," / ",ROUND(((A39+B39/2)*(F39/100)*30)/B39,2)) -> 2.38 / 1.33
A40: 0.44 | B40: 0.12 | C40: 0.72 | D40: 1.1 | E40: 1.82 | F40: 1.15 | G40: =CONCATENATE(ROUND(((A40+B40/2)*(E40/100)*30)/B40,2)," / ",ROUND(((A40+B40/2)*(F40/100)*30)/B40,2)) -> 2.28 / 1.44
A41: 0.56 | B41: 0.15 | C41: 0.7 | D41: 1.1 | E41: 1.8 | F41: 1 | G41: =CONCATENATE(ROUND(((A41+B41/2)*(E41/100)*30)/B41,2)," / ",ROUND(((A41+B41/2)*(F41/100)*30)/B41,2)) -> 2.29 / 1.27
A42: 0.71 | B42: 0.15 | C42: 0.56 | D42: 0.8 | E42: 1.36 | F42: 0.8 | G42: =CONCATENATE(ROUND(((A42+B42/2)*(E42/100)*30)/B42,2)," / ",ROUND(((A42+B42/2)*(F42/100)*30)/B42,2)) -> 2.14 / 1.26
A43: 0.86 | B43: 0.18 | C43: 0.55 | D43: 0.8 | E43: 1.35 | F43: 0.75 | G43: =CONCATENATE(ROUND(((A43+B43/2)*(E43/100)*30)/B43,2)," / ",ROUND(((A43+B43/2)*(F43/100)*30)/B43,2)) -> 2.14 / 1.19
...

Sheet Harvest Schedule
A1: Harvest Schedule
A2: Each event's weight comes from the Growth Model's growth curve (or a count-per-kg override for shrimp). Population and biomass cascade forward automatically after every harvest event.
A3: Defaults below reflect IMC (partial harvest ~1 kg, final ~1.5 kg). For P. vannamei, use 4 events at 80/60/40/30 count; for P. monodon, use 2 events at 30 count then a final 10-20 count (avg. 15 count). Edit Day, Count and % Harvested to match your species after switching Culture Type on the Dashboard.
A5: Total Stocked Number (Growth Model reference) | B5: ='Growth & Feed Model'!B7 -> 6250 | C5: nos.
A6: Estimated Standing Biomass at Culture End (Growth Model reference) | B6: ='Growth & Feed Model'!B26 -> 7500 | C6: kg | D6: Compare against total harvested quantity below
A8: Harvest Events
A9: Harvest Event (editable label) | B9: Day | C9: Count per kg (shrimp, optional) | D9: Weight Used (g) | E9: Population Before Event | F9: % of Remaining Population Harvested | G9: Population Harvested | H9: Quantity Harvested (kg) | I9: Population Remaining After
A10: Partial Harvest | B10: =IFERROR(INDEX($B$22:$B$26,MATCH(Dashboard!$B$5,$A$22:$A$26,0)),"") -> 200 | C10: =IFERROR(INDEX($C$22:$C$26,MATCH(Dashboard!$B$5,$A$22:$A$26,0)),"") -> 0 | D10: =IF(OR(C10="",C10=0),IF(OR(B10="",B10=0),"",IF('Growth & Feed Model'!$B$29="Logistic (Sigmoidal)",'Growth & Feed Model'!$B$30/(1+(('Growth & Feed Model'!$B$30-'Growth & Feed Model'!$B$8)/'Growth & Feed Model'!$B$8)*EXP(-'Growth & Feed Model'!$B$31*B10)),'Growth & Feed Model'!$B$8*EXP('Growth & Feed Model'!$B$13*B10))),1000/C10) -> 1021.9381 | E10: =$B$5 -> 6250 | F10: =IFERROR(INDEX($D$22:$D$26,MATCH(Dashboard!$B$5,$A$22:$A$26,0)),"") -> 0.2 | G10: =E10*F10 -> 1250 | H10: =IF(D10="",0,G10*D10/1000) -> 1277.4226 | I10: =E10-G10 -> 5000
A11: Final Harvest | B11: =IFERROR(INDEX($E$22:$E$26,MATCH(Dashboard!$B$5,$A$22:$A$26,0)),"") -> 240 | C11: =IFERROR(INDEX($F$22:$F$26,MATCH(Dashboard!$B$5,$A$22:$A$26,0)),"") -> 0 | D11: =IF(OR(C11="",C11=0),IF(OR(B11="",B11=0),"",IF('Growth & Feed Model'!$B$29="Logistic (Sigmoidal)",'Growth & Feed Model'!$B$30/(1+(('Growth & Feed Model'!$B$30-'Growth & Feed Model'!$B$8)/'Growth & Feed Model'!$B$8)*EXP(-'Growth & Feed Model'!$B$31*B11)),'Growth & Feed Model'!$B$8*EXP('Growth & Feed Model'!$B$13*B11))),1000/C11) -> 1500 | E11: =I10 -> 5000 | F11: =IFERROR(INDEX($G$22:$G$26,MATCH(Dashboard!$B$5,$A$22:$A$26,0)),"") -> 1 | G11: =E11*F11 -> 5000 | H11: =IF(D11="",0,G11*D11/1000) -> 7500 | I11: =E11-G11 -> 0
A12: Harvest Event 3 | B12: =IFERROR(INDEX($H$22:$H$26,MATCH(Dashboard!$B$5,$A$22:$A$26,0)),"") -> 0 | C12: =IFERROR(INDEX($I$22:$I$26,MATCH(Dashboard!$B$5,$A$22:$A$26,0)),"") -> 0 | D12: =IF(OR(C12="",C12=0),IF(OR(B12="",B12=0),"",IF('Growth & Feed Model'!$B$29="Logistic (Sigmoidal)",'Growth & Feed Model'!$B$30/(1+(('Growth & Feed Model'!$B$30-'Growth & Feed Model'!$B$8)/'Growth & Feed Model'!$B$8)*EXP(-'Growth & Feed Model'!$B$31*B12)),'Growth & Feed Model'!$B$8*EXP('Growth & Feed Model'!$B$13*B12))),1000/C12) | E12: =I11 -> 0 | F12: =IFERROR(INDEX($J$22:$J$26,MATCH(Dashboard!$B$5,$A$22:$A$26,0)),"") -> 0 | G12: =E12*F12 -> 0 | H12: =IF(D12="",0,G12*D12/1000) -> 0 | I12: =E12-G12 -> 0
A13: Harvest Event 4 | B13: =IFERROR(INDEX($K$22:$K$26,MATCH(Dashboard!$B$5,$A$22:$A$26,0)),"") -> 0 | C13: =IFERROR(INDEX($L$22:$L$26,MATCH(Dashboard!$B$5,$A$22:$A$26,0)),"") -> 0 | D13: =IF(OR(C13="",C13=0),IF(OR(B13="",B13=0),"",IF('Growth & Feed Model'!$B$29="Logistic (Sigmoidal)",'Growth & Feed Model'!$B$30/(1+(('Growth & Feed Model'!$B$30-'Growth & Feed Model'!$B$8)/'Growth & Feed Model'!$B$8)*EXP(-'Growth & Feed Model'!$B$31*B13)),'Growth & Feed Model'!$B$8*EXP('Growth & Feed Model'!$B$13*B13))),1000/C13) | E13: =I12 -> 0 | F13: =IFERROR(INDEX($M$22:$M$26,MATCH(Dashboard!$B$5,$A$22:$A$26,0)),"") -> 0 | G13: =E13*F13 -> 0 | H13: =IF(D13="",0,G13*D13/1000) -> 0 | I13: =E13-G13 -> 0
A15: TOTAL PRODUCTION | B15: =SUM(H10:H13) -> 8777.4226 | C15: kg | D15: Formula: Sum of all harvest quantities — this is the canonical production figure used downstream
A16: Variance vs. Growth Model Estimate | B16: =B15-B6 -> 1277.4226 | C16: kg | D16: Large variance suggests growth model defaults need site calibration
A17: Variance % | B17: =B16/B6 -> 0.17032302 | C17: %
A19: Species Harvest Defaults (v3.0) — auto-fills Day/Count/% above when Culture Type changes on the Dashboard
A20: The Day, Count per kg and % Harvested cells above are FORMULAS that read the row matching the current Culture Type below. To customize for your farm, simply type your own number directly into any of those cells — your typed value replaces the formula and stops auto-syncing for that cell. To restore auto-sync later, copy the formula back from the matching cell in the table below.
A21: Culture Type | B21: Ev.1 Day | C21: Ev.1 Count | D21: Ev.1 % | E21: Ev.2 Day | F21: Ev.2 Count | G21: Ev.2 % | H21: Ev.3 Day | I21: Ev.3 Count | J21: Ev.3 % | K21: Ev.4 Day | L21: Ev.4 Count | M21: Ev.4 %
A22: IMC | B22: 200 | D22: 0.2 | E22: 240 | G22: 1
A23: Pangasius | E23: 240 | G23: 1
A24: Red Pacu | E24: 240 | G24: 1
A25: P. vannamei | B25: 70 | C25: 80 | D25: 0.2 | E25: 85 | F25: 60 | G25: 0.25 | H25: 100 | I25: 40 | J25: 0.3 | K25: 120 | L25: 30 | M25: 1
A26: P. monodon | B26: 100 | C26: 30 | D26: 0.4 | E26: 150 | F26: 15 | G26: 1

Sheet Feed Emission Model
A1: Feed Emission Model (Scope 3)
A4: Reference Inputs
A5: Total Feed Required | B5: =IF(Dashboard!$B$29="",'Growth & Feed Model'!B25,Dashboard!$B$29) -> 20800.267 | C5: kg | D5: Actual Feed Used override if entered; otherwise modeled feed requirement.
A6: Feed Carbon Content | B6: =Dashboard!$B$27 -> 0.3925 | C6: %
A7: Feed Nitrogen Content | B7: =Dashboard!$B$28 -> 0.038928 | C7: %
A8: Feed Manufacturing Emission Factor | B8: =Dashboard!$B$26 -> 0.615 | C8: kgCO2e/kg
A9: MRV Feed Data Status | B9: =IF(Dashboard!$B$29="","MODELED","MEASURED") -> MODELED | C9: status
A10: Retention Efficiencies (Boyd / Avnimelech — editable)
A11: Carbon Retention Efficiency in Harvested Biomass | B11: 0.22 | C11: fraction | D11: Typical range 18-25%
A12: Nitrogen Retention Efficiency in Harvested Biomass | B12: 0.25 | C12: fraction | D12: Typical range 20-30%
A14: Feed Manufacturing & Mass Balance
A15: Feed Production Scope 3 CO2e | B15: =B5*B8/1000 -> 12.792164 | C15: tCO2e | D15: Formula: Feed (kg) x EF / 1000
A16: Total Feed Carbon Input | B16: =B5*B6 -> 8164.1046 | C16: kg C | D16: Formula: Feed (kg) x Carbon content %
A17: Carbon Retained in Harvested Biomass | B17: =B16*B11 -> 1796.103 | C17: kg C
A18: Carbon Lost to Pond (Sediment/Water) | B18: =B16-B17 -> 6368.0016 | C18: kg C | D18: Feeds into the Pond Emission Model
A19: Total Feed Nitrogen Input | B19: =B5*B7 -> 809.71278 | C19: kg N | D19: Formula: Feed (kg) x Nitrogen content %
A20: Nitrogen Retained in Harvested Biomass | B20: =B19*B12 -> 202.42819 | C20: kg N
A21: Nitrogen Lost to Pond (Water/Sediment) | B21: =B19-B20 -> 607.28458 | C21: kg N | D21: Feeds into the Pond Emission Model

Sheet Pond Emission Model
A1: Pond Emission Model (Scope 1 — CH4 & N2O)
A2: Baseline scenario. The Improved Farming Scenario sheet re-runs this logic with management-adjusted inputs.
A4: Reference Inputs
A5: Carbon Lost to Pond | B5: ='Feed Emission Model'!B18 -> 6368.0016 | C5: kg C | D5: From Feed Emission Model
A6: Nitrogen Lost to Pond | B6: ='Feed Emission Model'!B21 -> 607.28458 | C6: kg N | D6: From Feed Emission Model
A8: DO / Redox-Based Assumptions (baseline — editable, calibrate from field data)
A9: Anaerobic Fraction of Carbon Lost | B9: =IF(COUNT('Water Quality & Plankton Log'!$A$6:$A$65)=0,20%,IF(AND($G$44>=4,COUNTIF('Water Quality & Plankton Log'!$E$6:$E$65,"Detected")=0),12%,IF(AND($G$44<3,COUNTIF('Water Quality & Plankton Log'!$E$6:$E$65,"Detected")>0),30%,20%))) -> 0.2 | C9: fraction | D9: Dynamic from weekly pre-dawn DO and H₂S. No-data fallback = 20%.
A10: CH4 Oxidation Fraction (in water column before release) | B10: 0.25 | C10: fraction | D10: Fraction of produced CH4 re-oxidized to CO2 in the oxic surface layer
A11: N2O-N Emission Factor (% of Nitrogen Lost) | B11: =IF(B46="0.71%",0.0071,IF(B46="1.8%",0.018,B47))*IF(AND(ISNUMBER($G$45),$G$45>0.5),1.2,1) -> 0.008 | C11: fraction | D11: N2O-N EF preset adjusted +20% when average cyanobacteria exceeds 50%.
A12: GWP - CH4 (100-yr, AR5) | B12: =IF(B44="AR6",27,28) -> 28 | C12: multiplier | D12: Auto-computed from the GWP Standard toggle in Advanced Options below
A13: GWP - N2O (100-yr, AR5) | B13: =IF(B44="AR6",273,265) -> 265 | C13: multiplier | D13: Auto-computed from the GWP Standard toggle in Advanced Options below
A15: Optional Measured Flux Overrides (leave blank to use modelled estimate)
A16: Measured CH4 (kg CH4/crop) | C16: kg/crop | D16: From floating chamber measurement, if available
A17: Measured N2O (kg N2O/crop) | C17: kg/crop | D17: From floating chamber measurement, if available
A19: CH4 Calculation
A20: CH4-C Produced | B20: =B5*(1-B50)*B9*B45 -> 1273.6003 | C20: kg C | D20: Carbon lost, net of the Sediment Carbon Burial Fraction (Advanced Options below), x anaerobic fraction x adjustment factor
A21: CH4 Produced (gross, before oxidation) | B21: =B20*16/12 -> 1698.1338 | C21: kg CH4 | D21: Formula: CH4-C x (16/12)
A22: CH4 Emitted (after oxidation, modelled) | B22: =B21*(1-B10) -> 1273.6003 | C22: kg CH4 | D22: Formula: Gross CH4 x (1 - oxidation fraction)
A23: CH4 Emitted (used — measured override if provided) | B23: =IF(B16="",B22,B16) -> 1273.6003 | C23: kg CH4
A24: CH4 CO2e | B24: =B23*B12/1000 -> 35.660809 | C24: tCO2e
A26: N2O Calculation
A27: N2O Emission (modelled) | B27: =B6*B11*(44/28) -> 7.6344348 | C27: kg N2O | D27: Formula: Nitrogen lost x N2O-N EF% x (44/28)
A28: N2O Emission (used — measured override if provided) | B28: =IF(B17="",B27,B17) -> 7.6344348 | C28: kg N2O
A29: N2O CO2e | B29: =B28*B13/1000 -> 2.0231252 | C29: tCO2e
A31: Lime & Fertilizer Emissions (optional — set inputs to 0 if not applied)
A32: Agricultural Lime Applied | B32: 200 | C32: kg/crop | D32: Set to 0 if lime is not used
A33: Lime Emission Factor | B33: 0.12 | C33: tCO2/t lime | D33: IPCC 2019 Refinement to the 2006 Guidelines, AFOLU Vol. 4, Ch. 11 — Tier 1 default for calcitic limestone
A34: Synthetic Fertilizer Nitrogen Applied | B34: 0 | C34: kg N/crop | D34: Most pond systems rely on feed/organic nitrogen only — set to 0 if no fertilizer is applied
A35: Direct N2O-N Emission Factor for Fertilizer N | B35: 0.01 | C35: fraction | D35: IPCC Tier 1 default EF1 = 1% of applied N emitted as N2O-N
A37: Lime & Fertilizer CO2e Calculation
A38: Lime CO2e | B38: =B32/1000*B33 -> 0.024 | C38: tCO2e | D38: Formula: Lime (t) x Lime EF
A39: Fertilizer N2O Emission | B39: =B34*B35*(44/28) -> 0 | C39: kg N2O | D39: Formula: Fertilizer N x EF1 x (44/28)
A40: Fertilizer N2O CO2e | B40: =B39*B13/1000 -> 0 | C40: tCO2e | D40: Uses the GWP-N2O constant above
A41: TOTAL LIME & FERTILIZER CO2e | B41: =B38+B40 -> 0.024 | C41: tCO2e
A43: Advanced Options (v2.3) | F43: Dynamic Field-Derived Inputs
A44: GWP Standard | B44: =Dashboard!$B$14 -> AR5 | C44: AR5 / AR6 | D44: Synced from Dashboard Section A — edit the toggle there, not here | F44: Average Pre-Dawn DO | G44: =IFERROR(AVERAGE('Water Quality & Plankton Log'!$C$6:$C$65),"") | H44: mg/L
A45: Anaerobic Fraction Adjustment Factor | B45: =IF('Carbon Accounting'!$B$52>30,1.25,IF('Carbon Accounting'!$B$52>20,1.15,1)) -> 1.25 | C45: multiplier | D45: Derived from latest soil C:N risk band: ≤20=1.00; >20=1.15; >30=1.25. | F45: Average Cyanobacteria | G45: =IFERROR(AVERAGE('Water Quality & Plankton Log'!$I$6:$I$65),"") | H45: fraction
A46: N2O-N EF Preset | B46: Custom | C46: 0.71% / 1.8% / Custom | D46: 0.71% and 1.8% reflect the published low/high range of feed-N-based N2O emission factors; choose Custom to use the value below | F46: WQ Data Completeness | G46: =MIN(1,COUNT('Water Quality & Plankton Log'!$A$6:$A$65)/MAX(1,ROUNDUP((Dashboard!$B$55-Dashboard!$B$54+1)/7,0))) -> 0 | H46: fraction
A47: Custom N2O-N EF (used if preset = Custom) | B47: 0.008 | C47: fraction | D47: Only used when the preset above is set to Custom | F47: Anaerobic Fraction Status | G47: =IF($G$46<0.75,"REVIEW: WQ DATA <75%",IF($B$9=12%,"LOW ANAEROBIC RISK",IF($B$9=30%,"HIGH ANAEROBIC RISK","INTERMEDIATE"))) -> REVIEW: WQ DATA <75% | H47: status
F48: N2O Cyanobacteria Adjustment | G48: =IF(AND(ISNUMBER($G$45),$G$45>0.5),20%,0) -> 0 | H48: fraction
...

Sheet Energy Module
A1: Energy Module
A2: For IMC, Paddlewheel and Blower rows are hard-locked to zero. Energy boundary is water pumping, generator diesel and verified grid electricity.
A4: Aeration Reference (from Dashboard)
A5: Aeration Required for Selected Species | B5: =Dashboard!$B$23 -> 0 | C5: Yes/No
A7: Mechanical Aeration Inputs
A8: Paddlewheel Aerator Capacity | B8: 2 | C8: HP per unit
A9: Number of Paddlewheel Units | B9: =IF(Dashboard!$B$5="IMC",0,IFERROR(INDEX($B$41:$B$45,MATCH(Dashboard!$B$5,$A$41:$A$45,0)),0)) -> 0 | C9: units | D9: Set to 0 if aeration not required
A10: Paddlewheel Operating Hours | B10: =IF(Dashboard!$B$5="IMC",0,IFERROR(INDEX($C$41:$C$45,MATCH(Dashboard!$B$5,$A$41:$A$45,0)),0)) -> 0 | C10: hours/day
A11: Blower Capacity | B11: =IF(Dashboard!$B$5="IMC",0,IFERROR(INDEX($D$41:$D$45,MATCH(Dashboard!$B$5,$A$41:$A$45,0)),0)) -> 0 | C11: kW total | D11: Shrimp systems only; set 0 for fish ponds
A12: Blower Operating Hours | B12: =IF(Dashboard!$B$5="IMC",0,IFERROR(INDEX($E$41:$E$45,MATCH(Dashboard!$B$5,$A$41:$A$45,0)),0)) -> 0 | C12: hours/day
A14: Fuel & Grid Electricity Inputs
A15: Diesel Used (pumps/water exchange) | B15: 500 | C15: L/crop
A16: Generator Diesel (backup power) | B16: 200 | C16: L/crop
A17: Grid Electricity Purchased | B17: 500 | C17: kWh/crop | D17: Excluding paddlewheel/blower already captured above
A18: Solar Offset | B18: 0 | C18: kWh/crop | D18: Solar generation reducing grid draw
A20: Emission Factors (editable) | F20: CEA Database Version
A21: Diesel Emission Factor | B21: 3 | C21: kgCO2e/L | F21: 20.0
A22: Grid Electricity Emission Factor | B22: 0.71 | C22: kgCO2e/kWh | D22: CEA CO₂ Baseline Database Version 20.0 (FY2023-24 weighted-average grid EF shown as reference); verify the reporting-year CEA database before formal MRV submission. | F22: Reference FY
A23: CEA EF Provenance / Version Control | D23: Source: Central Electricity Authority, CO₂ Baseline Database. Reporting-year EF must be documented with the farm MRV record. | F23: FY2023-24
A24: Energy CO2e Calculation
A25: Paddlewheel Energy Demand | B25: =IF(Dashboard!$B$5="IMC",0,B8*0.746*B9*B10) -> 0 | C25: kWh/crop | D25: Formula: HP x 0.746 x units x hours
A26: Blower Energy Demand | B26: =IF(Dashboard!$B$5="IMC",0,B11*B12) -> 0 | C26: kWh/crop
A27: Total Electricity Demand | B27: =MAX(0,B25+B26+B17-B18) -> 500 | C27: kWh/crop | D27: Formula: Paddlewheel + Blower + Grid - Solar offset
A28: Electricity CO2e | B28: =B27*B22/1000 -> 0.355 | C28: tCO2e
A29: Diesel CO2e | B29: =(B15+B16)*B21/1000 -> 2.1 | C29: tCO2e
A30: TOTAL ENERGY CO2e | B30: =B28+B29 -> 2.455 | C30: tCO2e
A32: Generator Efficiency & Solar Sizing Guidance (v2.3, informational)
A33: Generator Fuel Efficiency | B33: 3.5 | C33: kWh output per L diesel | D33: Typical diesel genset range: 3-4 kWh/L. Informational only — diesel CO2e above is already calculated directly from liters burned, not from this figure.
A34: Generator Electrical Output (informational) | B34: =B16*B33 -> 700 | C34: kWh/crop | D34: Formula: Generator diesel (L) x efficiency — shows what the generator is delivering, does not change CO2e
A36: Solar offset sizing guidance: a 1 kWp rooftop/ground-mount solar installation typically generates roughly 4-5 kWh/day in most of India (more in Andhra Pradesh/Rajasthan-type high-irradiance zones, less in the monsoon season or cloudy regions). For a 200-day crop, a 1 kWp system installed for the full cycle could offset on the order of 800-1,000 kWh — size the Solar Offset input above against your actual installed capacity and crop duration rather than guessing.
A38: Species Aeration Defaults (v3.0) — auto-fills the aeration inputs above when Culture Type changes
A39: Species Aeration Defaults (IMC rows hard-locked; other species retain reference defaults)
A40: Culture Type | B40: Paddlewheel Units | C40: Paddlewheel Hours/day | D40: Blower Capacity (kW) | E40: Blower Hours/day | F40: Note
A41: IMC | B41: 0 | C41: 0 | D41: 0 | E41: 0 | F41: No aeration required
A42: Pangasius | B42: 0 | C42: 0 | D42: 0 | E42: 0 | F42: No aeration required
A43: Red Pacu | B43: 2 | C43: 6 | D43: 0 | E43: 0 | F43: Paddlewheel only
A44: P. vannamei | B44: 6 | C44: 16 | D44: 5 | E44: 16 | F44: Intensive — near-continuous aeration
A45: P. monodon | B45: 4 | C45: 10 | D45: 2 | E45: 10 | F45: Semi-intensive

Sheet Economics Module
A1: Economics Module
A2: Baseline-crop cost and income. Pairs with Carbon Accounting so the farm can see cost per kg alongside CO2e per kg.
A4: Reference Inputs
A5: Total Production | B5: ='Harvest Schedule'!B15 -> 8777.4226 | C5: kg | D5: From Harvest Schedule
A6: Total Feed Required | B6: ='Growth & Feed Model'!B25 -> 20800.267 | C6: kg | D6: From Growth & Feed Model
A7: Total Electricity Demand | B7: ='Energy Module'!B27 -> 500 | C7: kWh/crop | D7: From Energy Module
A8: Total Diesel Used | B8: ='Energy Module'!B15+'Energy Module'!B16 -> 700 | C8: L/crop | D8: From Energy Module
A9: Total Stocked Number | B9: ='Growth & Feed Model'!B7 -> 6250 | C9: nos. | D9: From Growth & Feed Model
A11: Price & Cost Inputs (editable — enter current local prices)
A12: Feed Price | B12: 45 | C12: Rs/kg | D12: Blended average across feed stages used
A13: Electricity Tariff | B13: 7 | C13: Rs/kWh | D13: Agricultural/commercial tariff as applicable
A14: Diesel Price | B14: 92 | C14: Rs/L
A15: Labour Cost | B15: 60000 | C15: Rs/crop | D15: Wages for the crop cycle
A16: Probiotics & Soil/Water Amendments Cost | B16: 25000 | C16: Rs/crop
A17: Seed Price | B17: 3.5 | C17: Rs/piece (fingerling or PL)
A18: Other Costs (lime, lease, misc.) | B18: 20000 | C18: Rs/crop
A19: Farm-Gate Sale Price | B19: 130 | C19: Rs/kg
A21: Cost Calculation
A22: Feed Cost | B22: =B6*B12 -> 936012 | C22: Rs | D22: Formula: Feed (kg) x Feed price
A23: Electricity Cost | B23: =B7*B13 -> 3500 | C23: Rs
A24: Diesel Cost | B24: =B8*B14 -> 64400 | C24: Rs
A25: Seed Cost | B25: =B9*B17 -> 21875 | C25: Rs | D25: Formula: Stocked number x Seed price
A26: TOTAL COST | B26: =B22+B23+B24+B25+B15+B16+B18 -> 1130787 | C26: Rs | D26: Formula: Feed + Electricity + Diesel + Seed + Labour + Probiotics + Other
A28: Income & Profitability
A29: Gross Income | B29: =B5*B19 -> 1141064.9 | C29: Rs | D29: Formula: Total production x Sale price
A30: NET PROFIT | B30: =B29-B26 -> 10277.944 | C30: Rs
A31: Cost per kg Production | B31: =B26/B5 -> 128.82905 | C31: Rs/kg
A32: Profit per kg Production | B32: =B30/B5 -> 1.1709524 | C32: Rs/kg
A34: Carbon-Economics Link
A35: Net Profit per tCO2e Reduced (Improved vs. Baseline) | B35: =IF('Carbon Reduction Summary'!B9=0,"",B30/'Carbon Reduction Summary'!B9) -> 367.94096 | C35: Rs/tCO2e | D35: Illustrates the cost-effectiveness case for carbon finance discussions
A37: Annual Rollup (Multi-Crop)
A38: Crops per Year | B38: =Dashboard!$B$12 -> 1 | C38: crops/yr | D38: From Dashboard
A39: Annual Production | B39: =B5*B38 -> 8777.4226 | C39: kg/yr
A40: Annual Total Cost | B40: =B26*B38 -> 1130787 | C40: Rs/yr
A41: Annual Gross Income | B41: =B29*B38 -> 1141064.9 | C41: Rs/yr
A42: ANNUAL NET PROFIT | B42: =B30*B38 -> 10277.944 | C42: Rs/yr

Sheet Improved Farming Scenario
A1: Improved Farming Scenario
A2: Select (Yes/No) the management changes to be applied. Effect sizes are editable, literature-informed defaults — replace with trial data where available.
A4: Management Measures
A5: Measure | B5: Apply? (Yes/No) | C5: FCR Improvement Effect | D5: Anaerobic Fraction Reduction Effect | E5: Other Effect
A6: Better Feed (quality/formulation) | B6: Yes | C6: 0.05 | D6: 0 | E6: Also reduces feed manufacturing EF by ~5% (higher-quality ingredient sourcing)
A7: Water Probiotics | B7: Yes | C7: 0.03 | D7: 0.3 | E7: Improves water-column DO stability
A8: Soil Probiotics | B8: Yes | C8: 0.02 | D8: 0.4 | E8: Bioremediates benthic organic load
A9: Better Aeration (Not applicable to IMC) | B9: No | C9: 0 | D9: 0 | E9: 0 | F9: Disabled for IMC to avoid artificial energy/CH₄ benefit.
A10: Water Quality Management (DO/Secchi monitoring) | B10: Yes | C10: 0.03 | D10: 0 | E10: Reduces N2O-N emission factor by ~20%
A12: Combined Effects (multiplicative — avoids double-counting)
A13: Combined FCR Improvement | B13: =1-(IF($B$6="Yes",1-$C$6,1)*IF($B$7="Yes",1-$C$7,1)*IF($B$8="Yes",1-$C$8,1)*IF($B$10="Yes",1-$C$10,1)*IF($B$36="Yes",1-$C$36,1)*IF(AND($B$38="Yes",Dashboard!$B$32<>"Yes"),1-$C$38,1)) -> 0.14154166 | C13: % | D13: Combines all measures marked Yes (multiplicative, not additive)
A14: Combined Anaerobic Fraction Reduction | B14: =1-(IF($B$6="Yes",1-$D$6,1)*IF($B$7="Yes",1-$D$7,1)*IF($B$8="Yes",1-$D$8,1)*IF($B$10="Yes",1-$D$10,1)*IF($B$37="Yes",1-$D$37,1)) -> 0.643 | C14: % | D14: Combines all measures marked Yes (multiplicative, not additive)
A15: Feed Manufacturing EF Reduction (if Better Feed applied) | B15: =IF(B6="Yes",0.05,0) -> 0.05 | C15: %
A16: Combined N2O-N EF Reduction (Water Quality Management + C/N Ratio Management) | B16: =1-(IF($B$10="Yes",1-0.2,1)*IF($B$37="Yes",1-$E$37,1)) -> 0.32 | C16: %
A17: Energy CO2e Increase (if Better Aeration applied) | B17: =0 -> 0 | C17: %
A19: Improved Scenario — Recalculated Totals
A20: Improved FCR | B20: =Dashboard!$B$30*(1-B13) -> 2.575375 | C20: ratio | F20: Baseline Growth Model already includes field-data Punch Bag/DO effects; Improved Scenario applies only incremental measures.
A21: Improved Total Feed Required | B21: ='Growth & Feed Model'!B25*(B20/Dashboard!$B$30) -> 17856.162 | C21: kg | D21: Scenario estimate relative to baseline FCR; compare with Growth Model dynamic feed requirement.
A22: Improved Feed Manufacturing EF | B22: ='Feed Emission Model'!B8*(1-B15) -> 0.58425 | C22: kgCO2e/kg
A23: Improved Feed Production Scope 3 CO2e | B23: =B21*B22/1000 -> 10.432463 | C23: tCO2e
A24: Improved Carbon Lost to Pond | B24: =B21*'Feed Emission Model'!B6*(1-'Feed Emission Model'!B11) -> 5466.6641 | C24: kg C
A25: Improved Anaerobic Fraction | B25: ='Pond Emission Model'!B9*(1-B14)*'Pond Emission Model'!B45 -> 0.08925 | C25: fraction
A26: Improved CH4 Emitted (after oxidation) | B26: =B24*(1-'Pond Emission Model'!B50)*B25*(16/12)*(1-'Pond Emission Model'!B10) -> 390.31982 | C26: kg CH4
A27: Improved CH4 CO2e | B27: =B26*'Pond Emission Model'!B12/1000 -> 10.928955 | C27: tCO2e
A28: Improved Nitrogen Lost to Pond | B28: =B21*'Feed Emission Model'!B7*(1-'Feed Emission Model'!B12) -> 521.32852 | C28: kg N
A29: Improved N2O-N EF | B29: ='Pond Emission Model'!B11*(1-B16) -> 0.00544 | C29: fraction
A30: Improved N2O Emission | B30: =B28*B29*(44/28) -> 4.4566141 | C30: kg N2O
A31: Improved N2O CO2e | B31: =B30*'Pond Emission Model'!B13/1000 -> 1.1810027 | C31: tCO2e
A32: Improved Energy CO2e | B32: ='Energy Module'!B30*(1+B17) -> 2.455 | C32: tCO2e
A34: Additional Measures (v2.3)
A35: Measure | B35: Apply? (Yes/No) | C35: FCR Improvement Effect | D35: Anaerobic Fraction Reduction Effect | E35: N2O-N EF Reduction Effect | F35: Note
A36: Optimized Feeding Timing (match feeding to DO/metabolic peaks) | B36: Yes | C36: 0.02 | D36: 0 | E36: 0 | F36: Small feed-efficiency gain from feeding when dissolved oxygen and metabolic rate are highest
A37: C/N Ratio Management (carbon source dosing, e.g. molasses/tapioca) | B37: Yes | C37: 0 | D37: 0.15 | E37: 0.15 | F37: Biofloc-style heterotrophic bacterial nitrogen immobilization reduces both anaerobic sediment loading and the nitrification-denitrification N2O pathway
A38: Punch Bag Feeding | B38: No | C38: 0.125 | D38: 0 | E38: 0 | F38: Apply 12.5% FCR improvement only when not already enabled in Dashboard/Growth Model; 10% wastage reduction is informational.

Sheet Carbon Accounting
A1: Carbon Accounting — Baseline vs. Improved
A4: Component | B4: Baseline | C4: Improved | D4: Unit | E4: Source
A5: Feed Production CO2e | B5: ='Feed Emission Model'!B15 -> 12.792164 | C5: ='Improved Farming Scenario'!B23 -> 10.432463 | D5: tCO2e | E5: Feed Emission Model / Improved Scenario
A6: Electricity CO2e | B6: ='Energy Module'!B28 -> 0.355 | C6: ='Energy Module'!B28*(1+'Improved Farming Scenario'!B17) -> 0.355 | D6: tCO2e | E6: Energy Module
A7: Diesel CO2e | B7: ='Energy Module'!B29 -> 2.1 | C7: ='Energy Module'!B29 -> 2.1 | D7: tCO2e | E7: Energy Module (assumed unchanged unless aeration measure adjusts pumping)
A8: CH4 CO2e | B8: ='Pond Emission Model'!B24 -> 35.660809 | C8: ='Improved Farming Scenario'!B27 -> 10.928955 | D8: tCO2e | E8: Pond Emission Model / Improved Scenario
A9: N2O CO2e | B9: ='Pond Emission Model'!B29 -> 2.0231252 | C9: ='Improved Farming Scenario'!B31 -> 1.1810027 | D9: tCO2e | E9: Pond Emission Model / Improved Scenario
A10: GROSS EMISSION | B10: =B5+B6+B7+B8+B9+'Pond Emission Model'!B41+'Pond Emission Model'!B53 -> 52.995098 | C10: =C5+C6+C7+C8+C9+'Pond Emission Model'!B41+'Pond Emission Model'!B53 -> 25.061421 | D10: tCO2e
A12: Carbon Stored in Harvested Biomass (netted out of pond-boundary footprint)
A13: Carbon Content of Harvested Biomass (wet weight) | B13: 0.08 | C13: fraction | D13: Typical range 6-10% wet weight for finfish/shrimp tissue
A14: Total Production (Baseline, from Harvest Schedule) | B14: ='Harvest Schedule'!B15 -> 8777.4226 | C14: kg
A15: Carbon Stored in Biomass (CO2e) | B15: =B14*B13*(44/12)/1000 -> 2.5747106 | C15: tCO2e | D15: Formula: Production x C content x (44/12) / 1000 — carbon leaving the pond boundary in product, not a permanent sequestration claim
A17: Net Emission & Intensity
A18: Net Emission — Baseline | B18: =B10-B15 -> 50.420388 | C18: tCO2e
A19: Net Emission — Improved | B19: =C10-B15 -> 22.48671 | C19: tCO2e | D19: Assumes same production — refine if improved FCR also changes yield
A20: Emission Intensity — Baseline | B20: =B18*1000/B14 -> 5.7443272 | C20: kgCO2e/kg
A21: Emission Intensity — Improved | B21: =B19*1000/B14 -> 2.5618807 | C21: kgCO2e/kg
A23: Lime, Fertilizer & Idle-Phase CO2e (included in Gross Emission above) | B23: ='Pond Emission Model'!B41+'Pond Emission Model'!B53 -> 0.064 | C23: tCO2e | D23: Assumed equal in Baseline and Improved scenarios unless lime/fertilizer use is deliberately changed
A25: Optional: Sediment Organic Carbon Accumulation (NOT included in Net Emission above)
A26: CAVEAT: SOC is measured from pre/post soil tests and converted with bulk density and sampling depth. Positive SOC change is potential storage; negative change indicates depletion. Permanence, leakage, sampling uncertainty and project methodology must be resolved before crediting.
A27: Measured Sediment Organic Carbon Accumulation Rate (derived) | B27: =IF(B69="","",B69/Dashboard!$B$10) | C27: t C/ha/yr | D27: Derived from repeat SOC measurements, bulk density, sampling depth and pond area; signed value retained.
A28: Measured Sediment Carbon Sequestration (informational only) | B28: =IF(B69="","",B70) | C28: tCO2e/yr | D28: Potential SOC accumulation only; not netted into Net Emission or Carbon Reduction Summary.
A30: Edible-Yield Emission Intensity
A31: Edible Yield Fraction | B31: 0.65 | C31: fraction | D31: Share of live/whole production that is edible product after dressing/processing losses — adjust per species and market form
A32: Edible Production | B32: =B14*B31 -> 5705.3247 | C32: kg | D32: Formula: Total production x Edible yield fraction
A33: Emission Intensity per kg Edible Yield — Baseline | B33: =B18*1000/B32 -> 8.8374265 | C33: kgCO2e/kg edible
A34: Emission Intensity per kg Edible Yield — Improved | B34: =B19*1000/B32 -> 3.941355 | C34: kgCO2e/kg edible
A36: Soil Test Log (v3.2) — matches routine IMC pond soil testing
A37: Confirmed field-testable parameters for IMC ponds: Soil Organic Carbon (SOC), Total Nitrogen, C:N ratio, CEC and Potassium are tested routinely; micronutrients (Fe, B, Zn, Mg) occasionally. Log results here each testing round — SOC% and C:N feed the sequestration estimate above and the nitrogen mass balance context; CEC/K/micronutrients are for pond fertility record-keeping.
A38: Test Date | B38: Soil Organic Carbon (%) | C38: Total N (%) | D38: C:N Ratio | E38: CEC (meq/100g) | F38: Potassium (K) (kg/ha) | G38: Sampling Phase | H38: Sample ID | I38: Bulk Density (g/cm³) | J38: Sampling Depth (m)
A52: Current Soil C:N (Pond Model link) | B52: =B71 | C52: ratio
A62: Measured Soil Carbon & Methanogenesis Risk
A63: Pre-Stocking SOC % | B63: =IFERROR(AVERAGEIF($G$39:$G$60,"Pre-Stocking",$B$39:$B$60),"") | C63: %
A64: Post-Harvest SOC % | B64: =IFERROR(AVERAGEIF($G$39:$G$60,"Post-Harvest",$B$39:$B$60),"") | C64: %
A65: Bulk Density | B65: =IFERROR(AVERAGEIFS($I$39:$I$60,$G$39:$G$60,"Pre-Stocking"),"") | C65: g/cm³
A66: Sampling Depth | B66: =IFERROR(AVERAGEIFS($J$39:$J$60,$G$39:$G$60,"Pre-Stocking"),"") | C66: m
A67: Pond Area | B67: =Dashboard!$B$10 -> 1 | C67: ha
A68: Actual SOC Change | B68: =IF(OR(B63="",B64="",B65="",B66=""),"",(B64-B63)/100*B65*B66*B67*10000) | C68: t C
A69: Annualized SOC Change | B69: =IF(OR(B68="",COUNTIF($G$39:$G$60,"Pre-Stocking")=0,COUNTIF($G$39:$G$60,"Post-Harvest")=0),"",B68*365/(AVERAGEIF($G$39:$G$60,"Post-Harvest",$A$39:$A$60)-AVERAGEIF($G$39:$G$60,"Pre-Stocking",$A$39:$A$60))) | C69: t C/yr
A70: SOC CO2e Equivalent (informational) | B70: =IF(B69="","",B69*44/12) | C70: tCO2e/yr
...

Sheet Carbon Reduction Summary
A1: Carbon Reduction Summary
A4: Traditional vs. Improved Farm
A5: Traditional Farm Net Emission | B5: ='Carbon Accounting'!B18 -> 50.420388 | C5: tCO2e/crop
A6: Improved Farm Net Emission | B6: ='Carbon Accounting'!B19 -> 22.48671 | C6: tCO2e/crop
A8: Reduction & Carbon Credit Potential
A9: CO2e Reduction per Crop | B9: =B5-B6 -> 27.933678 | C9: tCO2e
A10: % Reduction vs. Traditional | B10: =B9/B5 -> 0.55401553 | C10: %
A11: Potential Carbon Credit Equivalent per Year | B11: =B9*Dashboard!$B$12 -> 27.933678 | C11: tCO2e/yr
A12: Potential Carbon Credit Equivalent per Hectare per Year | B12: =B11/Dashboard!$B$10 -> 27.933678 | C12: tCO2e/ha/yr
A14: Screening-level estimate. Not a certified carbon credit figure — see Concept Note for MRV and methodology-pathway requirements before using this number in a funding submission or credit claim.

Sheet Sensitivity Analysis
A1: Sensitivity Analysis
A2: First-order approximate sensitivity — each block varies ONE driver at a time (FCR, Survival, Energy use, Anaerobic Fraction) around the baseline while holding everything else fixed, using the proportional relationships already in the model. This is a screening tool to show direction and rough magnitude, NOT a full re-simulation of the Growth Model, NOT a joint/combined-driver analysis, and NOT a substitute for measured field data. Real farm outcomes will differ, especially where drivers interact (e.g., FCR and survival both changing together). Treat results directionally and revisit with site-specific data before using in any external submission.
A4: A. FCR Sensitivity (feed-driven emissions and cost scale with FCR)
A5: Scenario | B5: % Change | C5: Driver Value | D5: Feed / Production (kg) | E5: Net Emission (tCO2e) | F5: Emission Intensity (kgCO2e/kg) | G5: Net Profit (Rs) | H5: Δ Net Profit vs. Base (Rs)
A6: -20% | B6: -0.2 | C6: =Dashboard!$B$30*(1+B6) -> 2.4 | D6: ='Economics Module'!$B$6*(C6/Dashboard!$B$30) -> 16640.213 | E6: =((('Carbon Accounting'!$B$5+'Carbon Accounting'!$B$8+'Carbon Accounting'!$B$9)*(D6/'Economics Module'!$B$6))+('Carbon Accounting'!$B$6+'Carbon Accounting'!$B$7+'Pond Emission Model'!$B$41+'Pond Emission Model'!$B$53))-'Carbon Accounting'!$B$15 -> 40.325168 | F6: =E6*1000/'Economics Module'!$B$5 -> 4.5941924 | G6: ='Economics Module'!$B$29-(D6*'Economics Module'!$B$12+'Economics Module'!$B$23+'Economics Module'!$B$24+'Economics Module'!$B$25+'Economics Module'!$B$15+'Economics Module'!$B$16+'Economics Module'!$B$18) -> 197480.34 | H6: =G6-G8 -> 187202.4
A7: -10% | B7: -0.1 | C7: =Dashboard!$B$30*(1+B7) -> 2.7 | D7: ='Economics Module'!$B$6*(C7/Dashboard!$B$30) -> 18720.24 | E7: =((('Carbon Accounting'!$B$5+'Carbon Accounting'!$B$8+'Carbon Accounting'!$B$9)*(D7/'Economics Module'!$B$6))+('Carbon Accounting'!$B$6+'Carbon Accounting'!$B$7+'Pond Emission Model'!$B$41+'Pond Emission Model'!$B$53))-'Carbon Accounting'!$B$15 -> 45.372778 | F7: =E7*1000/'Economics Module'!$B$5 -> 5.1692598 | G7: ='Economics Module'!$B$29-(D7*'Economics Module'!$B$12+'Economics Module'!$B$23+'Economics Module'!$B$24+'Economics Module'!$B$25+'Economics Module'!$B$15+'Economics Module'!$B$16+'Economics Module'!$B$18) -> 103879.14 | H7: =G7-G8 -> 93601.2
A8: Base | B8: 0 | C8: =Dashboard!$B$30*(1+B8) -> 3 | D8: ='Economics Module'!$B$6*(C8/Dashboard!$B$30) -> 20800.267 | E8: =((('Carbon Accounting'!$B$5+'Carbon Accounting'!$B$8+'Carbon Accounting'!$B$9)*(D8/'Economics Module'!$B$6))+('Carbon Accounting'!$B$6+'Carbon Accounting'!$B$7+'Pond Emission Model'!$B$41+'Pond Emission Model'!$B$53))-'Carbon Accounting'!$B$15 -> 50.420388 | F8: =E8*1000/'Economics Module'!$B$5 -> 5.7443272 | G8: ='Economics Module'!$B$29-(D8*'Economics Module'!$B$12+'Economics Module'!$B$23+'Economics Module'!$B$24+'Economics Module'!$B$25+'Economics Module'!$B$15+'Economics Module'!$B$16+'Economics Module'!$B$18) -> 10277.944 | H8: =G8-G8 -> 0
